File: ExpDat_PbSe 2 3-30-18 700.txt
#EXPORTTYPE:DATA ALL
#FILE:PbSe 2 3-30-18 700.ngb-ds1
#FORMAT:NETZSCH5
#FTYPE:ANSI
#IDENTITY:PbSe
#DECIMAL:POINT
#SEPARATOR:SEMICOLON
#MTYPE:DSC
#INSTRUMENT:NETZSCH STA 449F1
#PROJECT:
#DATE/TIME:30.03.2018 13:16
#CORR. FILE:PbSe correction 3-29-18 700C.ngb-bs1
#TEMPCAL:Peter Mouche Cal 1 9-10-2013.ngb-ts1
#SENSITIVITY:Peter Mouche Cal 9-10-2013.ngb-es1
#LABORATORY:
#OPERATOR:
#REMARK:
#SAMPLE:2
#SAMPLE MASS /mg:15.9
#MATERIAL:
#REFERENCE:empty crucible
#REFERENCE MASS /mg:0
#TYPE OF CRUCIBLE:DSC/TG pan Al2O3
#SAMPLE CRUCIBLE MASS /mg:0
#REFERENCE CRUCIBLE MASS /mg:0
#DSC RANGE /µV:5000
#TG RANGE /mg:5000
#TAU-R:---
#CORR. CODE:020
#EXO:-1
#RANGE:30°C/5.0(K/min)/90°C/10.0(K/min)/700°C/
#SEGMENT:S1-2/2
#SEG. 1:30°C/5.0(K/min)/90°C
#SEG. 2:90°C/10.0(K/min)/700°C

##Temp./°C;Time/min;DSC/(mW/mg);Mass loss/mg;Gas Flow(purge1)/(ml/min);Gas Flow(protective)/(ml/min);Sensit./(uV/mW);Segment
 25.03400; 0.00000; 4.1712e-002; 0.0000e+000;20.00000;30.00000;0.95708;1
 25.39348; 0.25000; 4.4280e-002;-1.2350e-002;20.00000;30.00000;0.95686;1
 25.75825; 0.50000; 4.5043e-002;-2.4300e-002;20.00000;30.00000;0.95663;1
 26.13610; 0.75000; 4.4452e-002;-3.3575e-002;20.00000;30.00000;0.95640;1
 26.53701; 1.00000; 4.4313e-002;-4.1950e-002;20.00000;30.00000;0.95615;1
 26.96801; 1.25000; 4.3070e-002;-5.3000e-002;20.00000;30.00000;0.95588;1
 27.43496; 1.50000; 4.1878e-002;-6.2200e-002;20.00000;30.00000;0.95559;1
 27.95684; 1.75000; 4.1390e-002;-7.0800e-002;20.00000;30.00000;0.95526;1
 28.52656; 2.00000; 4.0551e-002;-8.2600e-002;20.00000;30.00000;0.95491;1
 29.13889; 2.25000; 3.9763e-002;-9.4025e-002;20.00000;30.00000;0.95452;1
 29.79993; 2.50000; 4.0434e-002;    -0.10523;20.00000;30.00000;0.95411;1
 30.51065; 2.75000; 4.0755e-002;    -0.11718;20.00000;30.00000;0.95366;1
 31.26488; 3.00000; 3.9920e-002;    -0.12885;20.00000;30.00000;0.95319;1
 32.06235; 3.25000; 3.9739e-002;    -0.14083;20.00000;30.00000;0.95269;1
 32.91781; 3.50000; 3.9510e-002;    -0.15468;20.00000;30.00000;0.95215;1
 33.81795; 3.75000; 3.9685e-002;    -0.16925;20.00000;30.00000;0.95158;1
 34.77378; 4.00000; 3.9609e-002;    -0.18303;20.00000;30.00000;0.95098;1
 35.77199; 4.25000; 3.9686e-002;    -0.19888;20.00000;30.00000;0.95035;1
 36.81449; 4.50000; 3.9006e-002;    -0.21565;20.00000;30.00000;0.94969;1
 37.90839; 4.75000; 3.8023e-002;    -0.23155;20.00000;30.00000;0.94899;1
 39.04264; 5.00000; 3.6686e-002;    -0.25028;20.00000;30.00000;0.94827;1
 40.22869; 5.25000; 3.6057e-002;    -0.27230;20.00000;30.00000;0.94752;1
 41.45670; 5.50000; 3.4160e-002;    -0.29418;20.00000;30.00000;0.94674;1
 42.72753; 5.75000; 3.3936e-002;    -0.31693;20.00000;30.00000;0.94593;1
 44.04209; 6.00000; 3.3002e-002;    -0.33713;20.00000;30.00000;0.94509;1
 45.39091; 6.25000; 3.3489e-002;    -0.36450;20.00000;30.00000;0.94422;1
 46.77912; 6.50000; 3.0723e-002;    -0.39518;20.00000;30.00000;0.94333;1
 48.20659; 6.75000; 2.9327e-002;    -0.42538;20.00000;30.00000;0.94241;1
 49.65859; 7.00000; 3.0733e-002;    -0.45815;20.00000;30.00000;0.94148;1
 51.14700; 7.25000; 3.0152e-002;    -0.49580;20.00000;30.00000;0.94052;1
 52.66742; 7.50000; 2.6506e-002;    -0.53535;20.00000;30.00000;0.93954;1
 54.21694; 7.75000; 2.9091e-002;    -0.57605;20.00000;30.00000;0.93853;1
 55.79580; 8.00000; 3.1682e-002;    -0.61940;20.00000;30.00000;0.93751;1
 57.39263; 8.25000; 3.2998e-002;    -0.66770;20.00000;30.00000;0.93647;1
 59.01531; 8.50000; 3.2933e-002;    -0.71795;20.00000;30.00000;0.93541;1
 60.65642; 8.75000; 3.5846e-002;    -0.77278;20.00000;30.00000;0.93434;1
 62.31836; 9.00000; 3.6916e-002;    -0.83182;20.00000;30.00000;0.93325;1
 63.99405; 9.25000; 3.8453e-002;    -0.89210;20.00000;30.00000;0.93215;1
 65.67072; 9.50000; 3.9941e-002;    -0.95502;20.00000;30.00000;0.93105;1
 67.36378; 9.75000; 1.8008e-002;    -1.01160;20.00000;30.00000;0.92994;1
 69.06720;10.00000;-4.9595e-003;    -1.04755;20.00000;30.00000;0.92882;1
 70.77617;10.25000;-1.7379e-002;    -1.09505;20.00000;30.00000;0.92769;1
 72.49341;10.50000;-2.6981e-002;    -1.13915;20.00000;30.00000;0.92655;1
 74.20444;10.75000;-2.9399e-002;    -1.19205;20.00000;30.00000;0.92542;1
 75.92073;11.00000;-3.0059e-002;    -1.24910;20.00000;30.00000;0.92428;1
 77.63620;11.25000;-3.0304e-002;    -1.30837;20.00000;30.00000;0.92314;1
 79.34381;11.50000;-2.1858e-002;    -1.37655;20.00000;30.00000;0.92200;1
 81.04854;11.75000;-1.8081e-002;    -1.44760;20.00000;30.00000;0.92086;1
 82.73622;12.00000;-9.3904e-003;    -1.53514;20.00000;30.00000;0.91973;2
 84.45608;12.25000; 1.5313e-003;    -1.62687;20.00000;30.00000;0.91858;2
 86.19220;12.50000; 6.3551e-003;    -1.72482;20.00000;30.00000;0.91742;2
 87.98304;12.75000; 9.8018e-003;    -1.83332;20.00000;30.00000;0.91621;2
 89.84645;13.00000; 2.0622e-002;    -1.96951;20.00000;30.00000;0.91496;2
 91.77414;13.25000; 4.1317e-002;    -2.12209;20.00000;30.00000;0.91366;2
 93.78028;13.50000; 8.6280e-002;    -2.32196;20.00000;30.00000;0.91230;2
 95.85058;13.75000;     0.15484;    -2.56279;20.00000;30.00000;0.91090;2
 97.98625;14.00000;     0.22005;    -2.84541;20.00000;30.00000;0.90946;2
100.19582;14.25000;     0.23645;    -3.11839;20.00000;30.00000;0.90796;2
102.46376;14.50000;     0.20239;    -3.37327;20.00000;30.00000;0.90641;2
104.79966;14.75000;     0.12887;    -3.59303;20.00000;30.00000;0.90482;2
107.19176;15.00000; 3.6731e-002;    -3.78872;20.00000;30.00000;0.90319;2
109.64714;15.25000;-6.1248e-002;    -3.96355;20.00000;30.00000;0.90151;2
112.17111;15.50000;    -0.16200;    -4.11738;20.00000;30.00000;0.89978;2
114.73735;15.75000;    -0.26030;    -4.26276;20.00000;30.00000;0.89802;2
117.36620;16.00000;    -0.35257;    -4.39098;20.00000;30.00000;0.89622;2
120.03839;16.25000;    -0.44684;    -4.50340;20.00000;30.00000;0.89438;2
122.75476;16.50000;    -0.53501;    -4.61121;20.00000;30.00000;0.89250;2
125.51854;16.75000;    -0.60643;    -4.71381;20.00000;30.00000;0.89060;2
128.33584;17.00000;    -0.66574;    -4.82446;20.00000;30.00000;0.88865;2
131.18998;17.25000;    -0.71616;    -4.93555;20.00000;30.00000;0.88667;2
134.06403;17.50000;    -0.75794;    -5.05013;20.00000;30.00000;0.88468;2
136.98077;17.75000;    -0.79095;    -5.16928;20.00000;30.00000;0.88265;2
139.92268;18.00000;    -0.82418;    -5.30039;20.00000;30.00000;0.88060;2
142.87424;18.25000;    -0.85444;    -5.43156;20.00000;30.00000;0.87855;2
145.85009;18.50000;    -0.87968;    -5.57537;20.00000;30.00000;0.87647;2
148.84000;18.75000;    -0.89985;    -5.72887;20.00000;30.00000;0.87438;2
151.82233;19.00000;    -0.91412;    -5.89674;20.00000;30.00000;0.87230;2
154.81241;19.25000;    -0.92009;    -6.07672;20.00000;30.00000;0.87021;2
157.79345;19.50000;    -0.91655;    -6.27074;20.00000;30.00000;0.86812;2
160.77668;19.75000;    -0.90273;    -6.47837;20.00000;30.00000;0.86603;2
163.74521;20.00000;    -0.87916;    -6.70412;20.00000;30.00000;0.86395;2
166.70731;20.25000;    -0.84589;    -6.95190;20.00000;30.00000;0.86187;2
169.65336;20.50000;    -0.78714;    -7.22393;20.00000;30.00000;0.85980;2
172.58487;20.75000;    -0.71233;    -7.51987;20.00000;30.00000;0.85774;2
175.50841;21.00000;    -0.64791;    -7.83838;20.00000;30.00000;0.85568;2
178.40648;21.25000;    -0.60786;    -8.15407;20.00000;30.00000;0.85364;2
181.29758;21.50000;    -0.58235;    -8.47408;20.00000;30.00000;0.85161;2
184.17535;21.75000;    -0.57009;    -8.79223;20.00000;30.00000;0.84958;2
187.02449;22.00000;    -0.55434;    -9.11841;20.00000;30.00000;0.84758;2
189.87398;22.25000;    -0.54014;    -9.45418;20.00000;30.00000;0.84557;2
192.70142;22.50000;    -0.52163;    -9.79648;20.00000;30.00000;0.84358;2
195.50430;22.75000;    -0.50152;   -10.15039;20.00000;30.00000;0.84161;2
198.30662;23.00000;    -0.47071;   -10.52871;20.00000;30.00000;0.83963;2
201.07629;23.25000;    -0.44004;   -10.92360;20.00000;30.00000;0.83768;2
203.82263;23.50000;    -0.42039;   -11.32582;20.00000;30.00000;0.83575;2
206.55115;23.75000;    -0.41734;   -11.73563;20.00000;30.00000;0.83383;2
209.25581;24.00000;    -0.41885;   -12.13986;20.00000;30.00000;0.83192;2
211.94596;24.25000;    -0.45088;   -12.53596;20.00000;30.00000;0.83003;2
214.62813;24.50000;    -0.62425;   -12.84183;20.00000;30.00000;0.82814;2
217.30628;24.75000;    -0.86884;   -13.02151;20.00000;30.00000;0.82626;2
219.98015;25.00000;    -1.06284;   -13.15775;20.00000;30.00000;0.82438;2
222.64549;25.25000;    -1.19106;   -13.27856;20.00000;30.00000;0.82251;2
225.29003;25.50000;    -1.27376;   -13.39601;20.00000;30.00000;0.82065;2
227.91721;25.75000;    -1.35782;   -13.49934;20.00000;30.00000;0.81881;2
230.53040;26.00000;    -1.49877;   -13.53152;20.00000;30.00000;0.81697;2
233.12865;26.25000;    -1.59356;   -13.54062;20.00000;30.00000;0.81515;2
235.71714;26.50000;    -1.66364;   -13.54465;20.00000;30.00000;0.81334;2
238.28929;26.75000;    -1.71908;   -13.55080;20.00000;30.00000;0.81154;2
240.84346;27.00000;    -1.76532;   -13.55404;20.00000;30.00000;0.80975;2
243.38540;27.25000;    -1.80771;   -13.55753;20.00000;30.00000;0.80798;2
245.91873;27.50000;    -1.84673;   -13.55862;20.00000;30.00000;0.80621;2
248.42886;27.75000;    -1.88361;   -13.56403;20.00000;30.00000;0.80446;2
250.94197;28.00000;    -1.91950;   -13.56324;20.00000;30.00000;0.80271;2
253.44155;28.25000;    -1.95404;   -13.56478;20.00000;30.00000;0.80097;2
255.93288;28.50000;    -1.98827;   -13.57009;20.00000;30.00000;0.79924;2
258.41328;28.75000;    -2.02207;   -13.57314;20.00000;30.00000;0.79751;2
260.89113;29.00000;    -2.05690;   -13.57484;20.00000;30.00000;0.79579;2
263.36729;29.25000;    -2.08986;   -13.58137;20.00000;30.00000;0.79408;2
265.83127;29.50000;    -2.12369;   -13.58497;20.00000;30.00000;0.79237;2
268.29438;29.75000;    -2.15704;   -13.58807;20.00000;30.00000;0.79067;2
270.76147;30.00000;    -2.19110;   -13.59149;20.00000;30.00000;0.78896;2
273.21563;30.25000;    -2.22505;   -13.59557;20.00000;30.00000;0.78727;2
275.67650;30.50000;    -2.25985;   -13.59911;20.00000;30.00000;0.78558;2
278.13025;30.75000;    -2.29485;   -13.60267;20.00000;30.00000;0.78389;2
280.58275;31.00000;    -2.32966;   -13.61001;20.00000;30.00000;0.78220;2
283.03268;31.25000;    -2.36532;   -13.61373;20.00000;30.00000;0.78052;2
285.48525;31.50000;    -2.40032;   -13.61804;20.00000;30.00000;0.77885;2
287.92829;31.75000;    -2.43644;   -13.62291;20.00000;30.00000;0.77717;2
290.38078;32.00000;    -2.47219;   -13.62406;20.00000;30.00000;0.77550;2
292.83076;32.25000;    -2.50843;   -13.62868;20.00000;30.00000;0.77383;2
295.27871;32.50000;    -2.54366;   -13.63552;20.00000;30.00000;0.77216;2
297.72629;32.75000;    -2.58059;   -13.64106;20.00000;30.00000;0.77050;2
300.18159;33.00000;    -2.61756;   -13.64350;20.00000;30.00000;0.76884;2
302.63345;33.25000;    -2.65399;   -13.65053;20.00000;30.00000;0.76718;2
305.08321;33.50000;    -2.69088;   -13.65411;20.00000;30.00000;0.76552;2
307.53722;33.75000;    -2.72687;   -13.65763;20.00000;30.00000;0.76387;2
309.99895;34.00000;    -2.76255;   -13.66010;20.00000;30.00000;0.76221;2
312.46073;34.25000;    -2.79808;   -13.66743;20.00000;30.00000;0.76055;2
314.91937;34.50000;    -2.83601;   -13.67199;20.00000;30.00000;0.75890;2
317.38516;34.75000;    -2.87251;   -13.67683;20.00000;30.00000;0.75725;2
319.84765;35.00000;    -2.90792;   -13.67776;20.00000;30.00000;0.75561;2
322.31414;35.25000;    -2.94503;   -13.68433;20.00000;30.00000;0.75396;2
324.78712;35.50000;    -2.98246;   -13.68807;20.00000;30.00000;0.75232;2
327.25621;35.75000;    -3.01908;   -13.68817;20.00000;30.00000;0.75068;2
329.72630;36.00000;    -3.05519;   -13.69259;20.00000;30.00000;0.74904;2
332.19437;36.25000;    -3.09256;   -13.69496;20.00000;30.00000;0.74741;2
334.66218;36.50000;    -3.12856;   -13.69862;20.00000;30.00000;0.74578;2
337.13495;36.75000;    -3.16580;   -13.70052;20.00000;30.00000;0.74416;2
339.60437;37.00000;    -3.20178;   -13.69678;20.00000;30.00000;0.74254;2
342.07708;37.25000;    -3.23895;   -13.69709;20.00000;30.00000;0.74092;2
344.55168;37.50000;    -3.27442;   -13.69869;20.00000;30.00000;0.73930;2
347.02613;37.75000;    -3.30988;   -13.69541;20.00000;30.00000;0.73769;2
349.50305;38.00000;    -3.34449;   -13.69904;20.00000;30.00000;0.73607;2
351.98263;38.25000;    -3.37835;   -13.69964;20.00000;30.00000;0.73447;2
354.45573;38.50000;    -3.41320;   -13.69796;20.00000;30.00000;0.73287;2
356.92607;38.75000;    -3.44934;   -13.69849;20.00000;30.00000;0.73127;2
359.39928;39.00000;    -3.48485;   -13.69714;20.00000;30.00000;0.72968;2
361.87622;39.25000;    -3.52101;   -13.69785;20.00000;30.00000;0.72809;2
364.34947;39.50000;    -3.55720;   -13.69647;20.00000;30.00000;0.72651;2
366.82458;39.75000;    -3.59367;   -13.69550;20.00000;30.00000;0.72493;2
369.30537;40.00000;    -3.63029;   -13.69456;20.00000;30.00000;0.72335;2
371.77965;40.25000;    -3.66712;   -13.69618;20.00000;30.00000;0.72177;2
374.25892;40.50000;    -3.70374;   -13.69628;20.00000;30.00000;0.72020;2
376.73945;40.75000;    -3.73974;   -13.69668;20.00000;30.00000;0.71864;2
379.21260;41.00000;    -3.77389;   -13.69462;20.00000;30.00000;0.71708;2
381.69186;41.25000;    -3.80573;   -13.69666;20.00000;30.00000;0.71552;2
384.17180;41.50000;    -3.83666;   -13.69580;20.00000;30.00000;0.71397;2
386.65318;41.75000;    -3.86634;   -13.69369;20.00000;30.00000;0.71242;2
389.13648;42.00000;    -3.89566;   -13.69440;20.00000;30.00000;0.71088;2
391.61855;42.25000;    -3.92339;   -13.69367;20.00000;30.00000;0.70934;2
394.09518;42.50000;    -3.95187;   -13.69237;20.00000;30.00000;0.70781;2
396.57759;42.75000;    -3.97920;   -13.69855;20.00000;30.00000;0.70627;2
399.05660;43.00000;    -4.00614;   -13.69400;20.00000;30.00000;0.70475;2